input.in
10
o
9 B 1 RVUU 35 48
3 B 2 GDLV 19 46
6 S 3 XSKA 15 45
7 B 4 BMBG 3 63
9 C 1
1 S 5 NYDC 66 5
5 S 6 VIAF 62 60
5 B 7 AWYQ 20 66
0 B 8 UMGX 7 28
4 B 9 UTKS 65 59
6 S 10 BYHL 92 94
7 S 11 HTCW 29 9
7 S 12 HPEK 17 43
5 C 6
6 C 3
2 B 13 NQND 62 85
9 C 1
1 B 14 UEHG 52 60
0 C 8
6 C 10
4 C 9
8 B 15 ITTP 10 29
5 C 6
8 B 16 MSCS 75 87
1 C 14
8 B 17 KIVX 31 84
9 B 18 TJBR 23 90
9 B 19 SCGV 8 66
3 S 20 WYXT 75 23
9 B 21 XJQF 59 22
6 S 22 YQNH 1 24
7 C 4
3 B 23 MSCS 5 11
8 B 24 ZEPW 47 58
9 C 1
8 S 25 PTIU 59 12
3 C 2
3 B 26 AQVW 40 69
2 C 13
4 C 9
7 C 11
5 B 27 WOVD 77 73
6 B 28 EVDR 35 74
6 S 29 YGMO 41 65
1 C 5
5 S 30 YGMO 17 67
6 S 31 BVCZ 4 83
3 B 32 CDDQ 76 58
0 C 8
4 S 33 DMOP 22 3
1 B 34 RVSQ 31 57
1 S 35 XNIP 6 25
4 B 36 YQNH 23 74
9 S 37 EVDR 12 14
6 S 38 XTUB 38 71
3 C 26
4 C 36
7 S 39 NPQE 69 60
8 C 25
2 C 13
3 S 40 PTIU 57 13
9 C 18
8 C 17
7 S 41 ZEPW 30 78
4 S 42 XSKA 6 57
3 B 43 NYDC 65 45
9 S 44 TJBR 38 7
7 S 45 EZEJ 41 85
7 C 39
3 S 46 NCUF 93 69
3 B 47 XSKA 47 61
0 C 8
7 C 39
6 S 48 ZEPW 82 52
0 B 49 BYHL 54 95
2 B 50 UEHG 26 16
2 C 50
4 C 9
3 B 51 XJQF 69 88
6 B 52 SDWF 57 11
8 C 24
9 S 53 VSWR 62 71
4 C 9
9 S 54 MSCS 96 29
5 C 6
1 S 55 XRQW 95 58
5 C 27
7 C 45
3 S 56 YROU 35 13
6 B 57 NYCL 67 70
2 S 58 MSCS 27 35
3 C 43
5 C 30
2 B 59 AWYQ 87 59
5 C 6
1 S 60 AQVW 90 55
7 B 61 XTUB 69 48
1 S 62 ZEPW 11 79
1 B 63 HGYL 30 43
9 S 64 XTUB 92 78
6 C 29
8 C 17
2 C 13
5 C 27
8 B 65 JIQW 74 92
6 C 52
9 B 66 AWYQ 94 94
0 C 49
4 B 67 YALB 2 71
3 S 68 LOWL 25 30
3 C 68
5 C 27
5 S 69 EVDR 37 96
1 S 70 CHEC 54 18
4 S 71 KIVX 41 45
4 S 72 WYXT 61 42
7 B 73 PTIU 61 67
6 B 74 XSET 38 71
3 C 56
5 B 75 PTIU 19 7
9 S 76 YROU 55 96
4 B 77 NYCL 8 79
4 C 77
7 C 45
8 B 78 ZCGS 35 97
7 S 79 NCUF 69 38
9 S 80 RNHZ 92 60
3 S 81 URQH 12 77
2 S 82 YQNH 63 24
8 B 83 SKSW 90 5
5 S 84 MUPD 27 98
7 B 85 NYCL 57 26
6 B 86 RVUU 41 45
0 C 8
9 C 80
5 C 69
3 B 87 MUPD 30 24
8 S 88 KHSP 99 77
5 B 89 VSWR 52 73
9 C 66
5 C 84
2 S 90 BEJW 61 57
1 S 91 EZEJ 49 77
3 B 92 OATT 42 6
8 C 78
4 B 93 SCAR 31 69
0 S 94 LTMN 64 34
2 B 95 EVDR 41 42
0 C 49
4 C 71
6 C 28
7 C 4
7 B 96 EWNH 92 39
1 C 91
6 B 97 SDWF 21 36
5 B 98 SCAR 46 9
9 C 80
8 C 24
5 C 30
6 S 99 ZEPW 5 72
8 S 100 YXYY 87 21
3 B 101 XUNX 22 78
5 S 102 YVUD 35 3
8 C 65
0 C 94
3 B 103 WPEU 17 79
0 C 8
0 C 94
3 S 104 SKSW 16 25
2 S 105 TWUW 33 4
9 B 106 SCAR 80 19
5 B 107 NYDC 66 27
5 C 89
3 B 108 ZEWU 34 59
6 S 109 BYHL 19 32
8 B 110 NYCL 86 31
5 S 111 KIVX 84 3
2 C 82
1 S 112 ZEPW 40 85
5 B 113 HGYL 4 62
9 C 19
2 S 114 WSQY 74 33
7 C 85
2 S 115 LTMN 7 18
2 C 82
4 S 116 UMGX 25 4
2 C 114
6 C 74
8 C 88
4 S 117 YXYY 62 51
2 C 82
1 B 118 YGMO 20 23
6 S 119 SDWF 29 21
4 C 72
8 S 120 RDKO 90 12
2 B 121 AWYQ 97 46
7 B 122 NQND 61 84
9 C 18
2 C 121
8 C 15
5 C 27
2 B 123 EWNH 65 17
9 C 64
8 C 88
2 C 95
1 S 124 MSCS 16 33
3 C 32
1 S 125 SKSW 8 95
7 C 12
2 C 82
8 B 126 HTCW 76 58
7 C 4
8 C 126
8 B 127 KPSG 14 24
6 S 128 XHCN 100 80
3 C 104
8 C 100
4 C 42
9 C 64
5 S 129 PNDD 78 53
6 B 130 CDDQ 56 91
2 B 131 XNIP 47 14
5 S 132 UMGX 59 62
6 B 133 LOWL 48 23
9 C 37
2 B 134 VHXS 56 35
9 B 135 MUPD 33 48
9 B 136 NCUF 89 48
7 S 137 BKKM 35 53
9 C 37
6 C 10
2 B 138 RVSQ 80 12
2 S 139 RNHZ 52 18
9 B 140 RVSQ 10 6
0 B 141 DMOP 93 61
9 B 142 ZCGS 26 63
1 C 35
3 C 87
1 B 143 HTCW 3 17
0 B 144 ZCGS 38 21
1 B 145 ZEWU 54 97
9 B 146 URQH 83 60
9 S 147 TWUW 32 61
3 C 81
4 S 148 NYDC 37 43
2 C 50
7 C 45
0 S 149 NYDC 8 52
0 B 150 WYXT 66 31
1 S 151 HPEK 5 5
6 C 99
0 C 94
2 B 152 KHSP 89 2
4 B 153 JOFY 54 85
3 C 32
9 B 154 NYDC 38 53
3 B 155 RYCL 34 9
3 C 43
6 S 156 NCUF 70 47
1 S 157 TWUW 61 44
1 B 158 WQKL 42 59
9 C 54
3 S 159 KPSG 26 16
7 C 96
0 B 160 SKSW 99 79
4 S 161 LQES 18 68
4 B 162 MSCS 98 83
5 B 163 DMOP 78 20
8 B 164 SKSW 12 86
1 B 165 YXYY 21 14
2 C 58
3 C 2
8 S 166 SCAR 71 13
2 C 105
4 S 167 SDWF 100 77
1 B 168 NPQE 10 34
9 C 1
8 B 169 HGYL 86 92
7 B 170 PKRP 60 27
4 C 67
2 B 171 NCUF 38 91
4 S 172 OYBX 21 73
1 S 173 MSCS 27 35
7 B 174 XSKA 59 17
3 C 2
2 S 175 AVYQ 49 96
9 C 64
5 B 176 EVDR 64 9
5 S 177 ZCGS 15 100
9 S 178 PNDD 92 91
4 S 179 NCUF 31 55
6 C 99
9 B 180 WOVD 77 62
8 C 88
7 S 181 XRQW 90 93
8 B 182 AUZJ 49 57
9 B 183 CHEC 82 85
2 S 184 SNCF 1 54
6 S 185 KHSP 76 86
5 B 186 ZSBO 59 2
8 C 110
9 B 187 KPSG 97 8
8 S 188 TDEN 3 27
7 C 12
0 B 189 NYCL 73 11
3 B 190 UTKS 89 44
8 S 191 DMOP 49 25
7 C 137
0 S 192 OLHO 81 56
1 B 193 LOWL 26 58
9 S 194 GDLV 15 13
7 S 195 BKKM 73 35
8 B 196 KIVX 88 92
0 B 197 ZEWU 62 5
9 B 198 KPSG 76 24
5 S 199 WSQY 30 40
9 B 200 BMBG 64 40
1 S 201 YGMO 1 60
9 B 202 ZCGS 21 75
8 S 203 NPQE 40 25
8 C 169
5 B 204 VSDS 21 48
7 S 205 VHXS 90 87
9 B 206 BVCZ 76 94
5 C 111
3 B 207 VIAF 100 43
5 C 111
5 B 208 SCGV 42 11
3 S 209 BYHL 8 15
6 S 210 EWNH 16 41
1 B 211 PTIU 2 98
9 C 64
5 B 212 ZSBO 42 27
6 C 133
8 C 169
2 S 213 VSWR 100 42
2 C 13
8 B 214 SCGV 9 63
1 S 215 JOFY 30 42
8 C 65
7 B 216 URQH 21 74
3 B 217 APVJ 32 49
8 S 218 TDEN 82 29
6 S 219 BVCZ 16 53
2 B 220 YROU 78 53
4 S 221 BVCZ 81 95
3 S 222 YVUD 87 21
9 S 223 TJBR 98 74
9 B 224 XSKA 94 1
1 S 225 AVYQ 68 88
5 S 226 YROU 22 70
5 C 98
3 B 227 HPEK 66 44
4 B 228 CMEU 56 57
5 S 229 URQH 50 90
7 C 181
1 C 193
9 C 76
6 S 230 OATT 99 88
9 S 231 IEEO 36 42
5 B 232 EWNH 15 81
3 C 217
8 C 110
3 C 103
0 S 233 RVSQ 13 58
5 C 232
6 B 234 BEJW 93 30
6 S 235 MPFI 71 13
4 S 236 AUZJ 75 2
0 S 237 XNIP 54 69
6 B 238 UEHG 8 75
0 S 239 RYCL 80 20
0 C 192
0 B 240 YVTW 67 24
1 B 241 RYCL 25 90
9 B 242 JIQW 11 29
5 B 243 YQNH 45 53
2 S 244 YROU 35 69
0 C 192
8 B 245 JOFY 34 48
9 C 224
5 S 246 LTMN 10 14
5 C 107
0 S 247 XSET 37 73
8 C 16
6 B 248 YVTW 60 52
6 S 249 OATT 15 34
9 C 44
5 B 250 SKSW 13 77
9 B 251 OMAI 61 61
7 B 252 HGYL 56 56
6 C 86
2 S 253 KHSP 70 2
3 C 20
2 B 254 BYHL 47 31
5 C 75
5 C 107
3 S 255 NYCL 63 75
3 B 256 CDDQ 96 81
6 B 257 YROU 77 40
5 B 258 WYXT 65 22
5 B 259 KIVX 56 38
8 B 260 JIQW 59 68
3 S 261 AWYQ 19 85
0 C 49
4 S 262 HTCW 5 29
5 B 263 TDEN 92 41
7 B 264 XRQW 48 58
3 C 209
7 B 265 NQND 40 88
8 S 266 BEJW 60 69
4 B 267 XJQF 55 13
2 C 131
1 C 173
9 B 268 KPSG 2 26
9 C 180
4 C 221
9 B 269 PKRP 80 58
5 C 163
4 S 270 HGYL 24 29
4 S 271 EWNH 45 24
6 C 99
4 C 270
3 B 272 KPSG 83 86
6 C 29
1 B 273 TJBR 56 14
6 S 274 VSWR 81 98
1 S 275 AUZJ 64 14
4 B 276 TJBR 28 83
8 C 191
8 C 65
9 B 277 MUPD 71 40
9 C 224
3 S 278 NYDC 64 23
0 B 279 XGDW 76 29
4 B 280 KIVX 43 9
8 B 281 XNIP 83 76
6 S 282 HTCW 77 13
3 S 283 SNCF 22 79
7 C 45
3 S 284 YALB 18 32
1 S 285 OYBX 52 7
7 C 61
2 S 286 RYCL 58 9
9 S 287 VSWR 99 79
2 S 288 YGMO 53 61
1 S 289 AVYQ 41 19
6 S 290 NYCL 75 15
9 B 291 NPCY 77 8
8 S 292 EZEJ 2 75
3 C 222
3 B 293 ITTP 41 36
5 B 294 JOFY 12 31
0 C 240
1 C 112
9 C 154
1 S 295 WOVD 100 54
1 C 289
3 B 296 HPEK 75 1
6 B 297 YROU 31 98
1 B 298 KVYX 14 84
3 S 299 ZCGS 61 21
8 B 300 OYBX 50 68
1 S 301 ZCGS 53 39
3 C 283
1 B 302 MUPD 54 63
2 B 303 LOWL 97 46
2 C 90
2 C 105
9 S 304 RDKO 62 47
5 S 305 HGYL 52 9
1 B 306 XGDW 10 17
3 S 307 YVTW 10 14
2 C 50
5 B 308 RVUU 51 59
0 B 309 UMGX 96 42
2 B 310 KIVX 46 71
6 C 48
3 B 311 MPFI 78 34
7 S 312 OLHO 33 67
7 S 313 PNDD 18 15
2 B 314 SNCF 4 50
4 B 315 CHEC 77 92
7 S 316 IEEO 21 12
2 B 317 OATT 25 70
6 B 318 UTKS 65 49
9 B 319 SKSW 96 95
1 B 320 NQND 18 63
8 C 281
9 B 321 YALB 81 32
2 C 134
4 S 322 APVJ 13 23
9 B 323 RYCL 76 64
0 S 324 XSET 31 31
1 B 325 APVJ 75 22
4 B 326 JPQK 50 99
9 C 66
2 S 327 KIVX 16 99
8 C 110
3 C 299
0 B 328 BYHL 77 62
5 C 102
7 B 329 EZEJ 26 7
8 C 166
1 B 330 RVSQ 26 39
6 B 331 BYHL 70 10
5 B 332 CMEU 50 18
0 C 94
5 B 333 CUKD 64 74
8 B 334 PNDD 67 98
4 B 335 BVCZ 26 21
9 B 336 APVJ 82 53
1 B 337 YQNH 26 77
3 C 207
2 C 244
1 S 338 VHXS 83 24
2 S 339 ZCGS 93 2
7 B 340 SCGV 86 12
4 S 341 LTMN 77 83
4 B 342 NYDC 4 35
3 C 272
2 C 310
9 S 343 EZEJ 88 30
7 C 312
1 B 344 VSWR 90 75
6 S 345 APVJ 4 40
2 C 152
8 B 346 YALB 32 18
7 C 79
6 C 257
5 B 347 XJQF 20 9
0 S 348 AVYQ 48 49
1 S 349 OMAI 12 59
2 S 350 SKSW 45 65
2 S 351 NYCL 36 85
9 B 352 WSQY 97 99
1 B 353 AVYQ 23 82
9 S 354 SDWF 2 46
2 C 303
1 B 355 XHCN 45 54
9 C 304
3 S 356 CDDQ 8 29
9 C 54
9 C 277
2 S 357 ZEWU 81 40
0 C 160
9 B 358 JIQW 26 71
5 S 359 UTKS 92 83
